<mujoco model="ur10e">
  <compiler angle="radian" meshdir="assets" autolimits="true"/>

  <option integrator="implicitfast"/>

  <default>
    <default class="ur10e">
      <material specular="0.5" shininess="0.25"/>
      <joint axis="0 1 0" range="-6.28319 6.28319" armature="0.1"/>
      <position ctrlrange="-6.2831 6.2831"/>
      <general biastype="affine" ctrlrange="-6.2831 6.2831" gainprm="5000" biasprm="0 -5000 -500"/>
      <default class="size4">
        <joint damping="10"/>
        <general forcerange="-330 330"/>
      </default>
      <default class="size3">
        <joint damping="5"/>
        <general forcerange="-150 150"/>
        <default class="size3_limited">
          <joint range="-3.1415 3.1415"/>
          <general ctrlrange="-3.1415 3.1415"/>
        </default>
      </default>
      <default class="size2">
        <joint damping="2"/>
        <general forcerange="-56 56"/>
      </default>
      <default class="visual">
        <geom type="mesh" contype="0" conaffinity="0" group="2"/>
      </default>
      <default class="collision">
        <geom type="capsule" group="3"/>
        <default class="eef_collision">
          <geom type="cylinder"/>
        </default>
      </default>
      <site size="0.001" rgba="0.5 0.5 0.5 0.3" group="4"/>
    </default>
  </default>

  <asset>
    <material class="ur10e" name="black" rgba="0.033 0.033 0.033 1"/>
    <material class="ur10e" name="jointgray" rgba="0.278 0.278 0.278 1"/>
    <material class="ur10e" name="linkgray" rgba="0.82 0.82 0.82 1"/>
    <material class="ur10e" name="urblue" rgba="0.49 0.678 0.8 1"/>
    <texture name="wood_texture" type="2d" file="assets/wood.png" />
    <material name="wood_material" texture="wood_texture" specular="0.3" shininess="0.1" />
    <texture name="shelf_wood_texture" type="2d" file="assets/shelf_wood.png" />
    <material name="shelf_wood_material" texture="shelf_wood_texture" specular="0.3" shininess="0.1" texrepeat="1 1" texuniform="true" />

    <mesh file="base_0.obj"/>
    <mesh file="base_1.obj"/>
    <mesh file="shoulder_0.obj"/>
    <mesh file="shoulder_1.obj"/>
    <mesh file="shoulder_2.obj"/>
    <mesh file="upperarm_0.obj"/>
    <mesh file="upperarm_1.obj"/>
    <mesh file="upperarm_2.obj"/>
    <mesh file="upperarm_3.obj"/>
    <mesh file="forearm_0.obj"/>
    <mesh file="forearm_1.obj"/>
    <mesh file="forearm_2.obj"/>
    <mesh file="forearm_3.obj"/>
    <mesh file="wrist1_0.obj"/>
    <mesh file="wrist1_1.obj"/>
    <mesh file="wrist1_2.obj"/>
    <mesh file="wrist2_0.obj"/>
    <mesh file="wrist2_1.obj"/>
    <mesh file="wrist2_2.obj"/>
    <mesh file="wrist3.obj"/>

    <texture name="texplane" type="2d" builtin="checker" rgb1=".2 .3 .4" rgb2=".1 0.15 0.2" width="100" height="100" />
    <material name="MatPlane" reflectance="0.5" texture="texplane" texrepeat="1 1" texuniform="true" />
    <material name="red_cover" rgba="1 0 0 1" />
        <!-- White material for the pages -->
    <material name="white_pages" rgba="1 1 1 1" />
  </asset>

  <!-- <visual>
      <global>
          <geommaterial>red_cover</geommaterial>
      </global>
  </visual> -->

  <worldbody>
    <!-- <geom name="floor" pos="0 0 0" size="500 500 0.125" type="plane" material="MatPlane" condim="3" group="2" rgba="0.8 0.9 0.8 1" /> -->
    <geom name="floor" pos="0 0 0" size="500 500 0.125" type="plane" material='shelf_wood_material' condim="3" group="2"/>
    <light name="spotlight" mode="targetbodycom" target="wrist_2_link" pos="0 -1 2"/>
    <camera pos="4.863 0.258 1.375" xyaxes="0 1 0.000 -0.215 0 1"/>
    <camera name="custom_view" pos="2.327 3.864 4.158" xyaxes="-0.834 0.552 0.000 -0.361 -0.545 0.757"/>
    <camera name="manipulation_view_1" pos="-0.420 -0.913 2.605" xyaxes="0.974 -0.227 -0.000 0.139 0.595 0.791"/>
    <camera name="manipulation_view_2" pos="1.440 -0.462 2.380" xyaxes="0.690 0.723 -0.000 -0.367 0.350 0.862"/>
    <!-- <camera name="obstacle_avoidance_view" pos="0.932 -1.957 1.066" xyaxes="0.951 0.308 -0.000 0.015 -0.046 0.999"/> -->
    <camera name="obstacle_avoidance_view" pos="0.710 -1.344 1.547" xyaxes="0.954 0.299 -0.000 -0.042 0.134 0.990"/>
    <!-- <camera  pos="0.777 -2.180 1.754" xyaxes="0.988 0.151 0.000 -0.021 0.139 0.990"/> -->
    <camera name="obstacle_avoidance_view_2" pos="0.520 -1.374 1.635" xyaxes="0.988 0.151 0.000 -0.021 0.139 0.990"/>
    <camera name="view_video_2" pos="-1.026 -0.726 2.226" xyaxes="0.606 -0.795 -0.000 0.359 0.274 0.892"/>
    <camera name="view_video_3" pos="0.484 -1.032 2.815" xyaxes="1.000 0.000 -0.000 -0.000 0.729 0.684"/>
    <camera name="view_video_4" pos="0.910 2.085 2.816" xyaxes="-0.939 0.345 0.000 -0.244 -0.664 0.707"/>






    <!-- 0.8 0.75 0.68 1 -->
    <body name="new_table" pos="0.3 1.0 0.75">
        <!-- Table top -->
        <geom name="table_top" type="box" size="1 0.7 0.025" pos="0 0 0.13" rgba='0.99 0.96 0.82 1' />
        
        <!-- Table legs -->
        <body name="table_leg1" pos="0.95 0.65 -0.323">
            <geom name="leg1" type="box" size="0.05 0.05 0.427" rgba='0.99 0.96 0.82 1'  />
        </body>
        <body name="table_leg2" pos="-0.95 0.65 -0.323">
            <geom name="leg2" type="box" size="0.05 0.05 0.427" rgba='0.99 0.96 0.82 1'  />
        </body>
        <body name="table_leg3" pos="0.95 -0.65 -0.323">
            <geom name="leg3" type="box" size="0.05 0.05 0.427" rgba='0.99 0.96 0.82 1'  />
        </body>
        <body name="table_leg4" pos="-0.95 -0.65 -0.323">
            <geom name="leg4" type="box" size="0.05 0.05 0.427" rgba='0.99 0.96 0.82 1'  />
        </body>
    </body>

    

    <!-- <site name="site1" pos="0 0 0" size="0.1" rgba="1 0 0 1"/>
    <site name="site2" pos="1 0 0" size="0.1" rgba="0.5 0.5 0 1"/>
    <site name="site3" pos="0 1 0" size="0.1" rgba="0 1 0 1"/> -->
    <!-- <site name="site4" pos="0 0 1" size="0.1" rgba="0 0 1 1"/> -->
    <site name="start_point" pos="-0.07 0.75 1.105" size="0.015" rgba="1 0 0 1"/>

    <site name="middle_point_1" pos="-0.03 0.75 1.165" size="0.015" rgba="0 1 0 0"/>
    <!-- <site name="middle_point_2" pos="0.01 0.75 1.225" size="0.015" rgba="0 1 0 1"/> -->
    <site name="middle_point_3" pos="0.05 0.75 1.275" size="0.015" rgba="0 1 0 0"/>
    <!-- <site name="middle_point_4" pos="0.1 0.75 1.305" size="0.015" rgba="0 1 0 1"/> -->
    <site name="middle_point_5" pos="0.15 0.75 1.330" size="0.015" rgba="0 1 0 0"/>
    <!-- <site name="middle_point_6" pos="0.2 0.75 1.365" size="0.015" rgba="0 1 0 1"/> -->
    <site name="middle_point_7" pos="0.25 0.75 1.40" size="0.015" rgba="0 1 0 0"/>
    <!-- <site name="middle_point_8" pos="0.3 0.75 1.455" size="0.015" rgba="0 1 0 1"/> -->
    <site name="middle_point_9" pos="0.35 0.75 1.48" size="0.015" rgba="0 1 0 0"/>
    <!-- <site name="middle_point_10" pos="0.4 0.75 1.530" size="0.015" rgba="0 1 0 1"/> -->
    <site name="middle_point_11" pos="0.47 0.75 1.530" size="0.015" rgba="0 1 0 0"/>
    <!-- <site name="middle_point_12" pos="0.54 0.75 1.490" size="0.015" rgba="0 1 0 1"/> -->
    <site name="middle_point_13" pos="0.60 0.75 1.460" size="0.015" rgba="0 1 0 0"/>
    <!-- <site name="middle_point_14" pos="0.67 0.75 1.410" size="0.015" rgba="0 1 0 1"/> -->
    <site name="middle_point_15" pos="0.74 0.75 1.35" size="0.015" rgba="0 1 0 0"/>
    <!-- <site name="middle_point_8" pos="0.43 1.16 1.505" size="0.015" rgba="0 1 0 0"/> -->

    <site name="goal_point" pos="0.8 0.75 1.305" size="0.015" rgba="1 0 0 1"/>

    <body name="robot_base" pos="0 0 0.5">
        <geom type="box" size="0.25 0.25 0.5" rgba="0.99 0.96 0.82 1"/>
    </body>

    <body name="behind_wall" pos="0 2.02 5.0">
        <geom type="box" size="5.0 0.3 5.0" rgba="0.745 0.64 0.545 1"/>
    </body>


    <!-- <body name="shelf_1" pos="0.155 1.36 1.305">
        <geom type="box" size="0.025 0.25 0.4" material='wood_material'/>
    </body>

    <body name="shelf_2" pos="0.705 1.36 1.305">
        <geom type="box" size="0.025 0.25 0.4" material='wood_material'/>
    </body>

    <body name="shelf_3" pos="0.43 1.36 1.305">
        <geom type="box" size="0.25 0.25 0.025" material='wood_material'/>
    </body>

    <body name="shelf_4" pos="0.43 1.36 0.93">
        <geom type="box" size="0.25 0.25 0.025" material='wood_material'/>
    </body>

    <body name="shelf_5" pos="0.43 1.36 1.68">
        <geom type="box" size="0.25 0.25 0.025" material='wood_material'/>
    </body>

    <body name="shelf_6" pos="0.43 1.625 1.305">
        <geom type="box" size="0.3 0.025 0.4" material='wood_material'/>
    </body> -->

    <body name="book_1" pos="0.10 0.75 1.03">
        <geom type="box" size="0.005 0.187 0.125" pos="0.035 0 0" rgba="0 1 0 1" />
        <geom type="box" size="0.005 0.187 0.125" pos="-0.035 0 0" rgba="0 1 0 1" />
        <geom type="box" size="0.04 0.187 0.005" pos="0 0 0.124" rgba="0 1 0 1" />
        <geom type="box" size="0.03 0.18 0.125" pos="0 0 0" rgba="1 1 1 1" />
    </body>

    <body name="book_2" pos="0.45 0.75 1.025">
        <geom type="box" size="0.005 0.187 0.125" pos="0.035 0 0" rgba="0 0 1 1" />
        <geom type="box" size="0.005 0.187 0.125" pos="-0.035 0 0" rgba="0 0 1 1" />
        <geom type="box" size="0.04 0.187 0.005" pos="0 0 0.124" rgba="0 0 1 1" />
        <geom type="box" size="0.03 0.18 0.125" pos="0 0 0" rgba="1 1 1 1" />
    </body>

    <body name="book_3" pos="0.80 0.75 1.025">
        <geom type="box" size="0.005 0.187 0.125" pos="0.035 0 0" rgba="1 1 0 1" />
        <geom type="box" size="0.005 0.187 0.125" pos="-0.035 0 0" rgba="1 1 0 1" />
        <geom type="box" size="0.04 0.187 0.005" pos="0 0 0.124" rgba="1 1 0 1" />
        <geom type="box" size="0.03 0.18 0.125" pos="0 0 0" rgba="1 1 1 1" />
    </body>

    <body name="book_4" pos="0.45 0.75 1.278">
        <geom type="box" size="0.005 0.187 0.125" pos="0.035 0 0" rgba="1 0 0 1" />
        <geom type="box" size="0.005 0.187 0.125" pos="-0.035 0 0" rgba="1 0 0 1" />
        <geom type="box" size="0.04 0.187 0.005" pos="0 0 0.124" rgba="1 0 0 1" />
        <geom type="box" size="0.03 0.18 0.125" pos="0 0 0" rgba="1 1 1 1" />
    </body>

    


    <body name="base" pos="0 0 1" quat="1 0 0 1" childclass="ur10e">
      <inertial mass="4.0" pos="0 0 0" diaginertia="0.0061063308908 0.0061063308908 0.01125"/>
      <geom name="base_0" mesh="base_0" material="black" class="visual"/>
      <geom name="base_1" mesh="base_1" material="jointgray" class="visual"/>
      <body name="shoulder_link" pos="0 0 0.181">
        <inertial pos="0 0 0" mass="7.778" diaginertia="0.0314743 0.0314743 0.0218756"/>
        <joint name="shoulder_pan_joint" class="size4" axis="0 0 1"/>
        <geom name="shoulder_0" mesh="shoulder_0" material="urblue" class="visual"/>
        <geom name="shoulder_1" mesh="shoulder_1" material="black" class="visual"/>
        <geom name="shoulder_2" mesh="shoulder_2" material="jointgray" class="visual"/>
        <geom name="shoulder_collision" class="collision" size="0.078 0.06" pos="0 0 -0.04"/>
        <body name="upper_arm_link" pos="0 0.176 0" quat="1 0 1 0">
          <inertial pos="0 0 0.3065" mass="12.93" diaginertia="0.423074 0.423074 0.0363656"/>
          <joint name="shoulder_lift_joint" class="size4"/>
          <geom name="upperarm_0" mesh="upperarm_0" material="black" class="visual"/>
          <geom name="upperarm_1" mesh="upperarm_1" material="jointgray" class="visual"/>
          <geom name="upperarm_2" mesh="upperarm_2" material="urblue" class="visual"/>
          <geom name="upperarm_3" mesh="upperarm_3" material="linkgray" class="visual"/>
          <geom name="upperarm_collision_1" class="collision" pos="0 -0.05 0" quat="1 1 0 0" size="0.078 0.08"/>
          <geom name="upperarm_collision_2" class="collision" size="0.06 0.3" pos="0 0 0.3"/>
          <body name="forearm_link" pos="0 -0.137 0.613">
            <inertial pos="0 0 0.2855" mass="3.87" diaginertia="0.11059 0.11059 0.0108844"/>
            <joint name="elbow_joint" class="size3_limited"/>
            <geom name="forearm_0" mesh="forearm_0" material="urblue" class="visual"/>
            <geom name="forearm_1" mesh="forearm_1" material="black" class="visual"/>
            <geom name="forearm_2" mesh="forearm_2" material="jointgray" class="visual"/>
            <geom name="forearm_3" mesh="forearm_3" material="linkgray" class="visual"/>
            <geom name="forearm_collision_1" class="collision" pos="0 0.08 0" quat="1 1 0 0" size="0.058 0.065"/>
            <geom name="forearm_collision_2" class="collision" size="0.043 0.28" pos="0 0 0.29"/>
            <body name="wrist_1_link" pos="0 0 0.571" quat="1 0 1 0">
              <inertial pos="0 0.135 0" quat="0.5 0.5 -0.5 0.5" mass="1.96"
                diaginertia="0.0055125 0.00510825 0.00510825"/>
              <joint name="wrist_1_joint" class="size2"/>
              <geom name="wrist1_0" mesh="wrist1_0" material="black" class="visual"/>
              <geom name="wrist1_1" mesh="wrist1_1" material="urblue" class="visual"/>
              <geom name="wrist1_2" mesh="wrist1_2" material="jointgray" class="visual"/>
              <geom name="wrist1_collision" class="collision" pos="0 0.06 0" quat="1 1 0 0" size="0.05 0.07"/>
              <body name="wrist_2_link" pos="0 0.135 0">
                <inertial pos="0 0 0.12" quat="0.5 0.5 -0.5 0.5" mass="1.96"
                  diaginertia="0.0055125 0.00510825 0.00510825"/>
                <joint name="wrist_2_joint" axis="0 0 1" class="size2"/>
                <geom name="wrist2_0" mesh="wrist2_0" material="black" class="visual"/>
                <geom name="wrist2_1" mesh="wrist2_1" material="urblue" class="visual"/>
                <geom name="wrist2_2" mesh="wrist2_2" material="jointgray" class="visual"/>
                <geom name="wrist2_collision_1" class="collision" size="0.046 0.065" pos="0 0 0.05"/>
                <geom name="wrist2_collision_2" class="collision" pos="0 0.028 0.12" quat="1 1 0 0" size="0.046 0.043"/>
                <body name="wrist_3_link" pos="0 0 0.12">
                  <inertial pos="0 0.092 0" quat="0 1 -1 0" mass="0.202"
                    diaginertia="0.000204525 0.000144346 0.000144346"/>
                  <joint name="wrist_3_joint" class="size2"/>
                  <geom name="wrist3" material="linkgray" mesh="wrist3" class="visual"/>
                  <geom name="eef_collision" class="eef_collision" pos="0 0.097 0" quat="1 1 0 0" size="0.046 0.02"/>
                  <site name="attachment_site" pos="0 0.1 0" quat="-1 1 0 0"/>
                </body>
              </body>
            </body>
          </body>
        </body>
      </body>
    </body>
  </worldbody>

  <actuator>
    <general class="size4" name="shoulder_pan" joint="shoulder_pan_joint"/>
    <general class="size4" name="shoulder_lift" joint="shoulder_lift_joint"/>
    <general class="size3_limited" name="elbow" joint="elbow_joint"/>
    <general class="size2" name="wrist_1" joint="wrist_1_joint"/>
    <general class="size2" name="wrist_2" joint="wrist_2_joint"/>
    <general class="size2" name="wrist_3" joint="wrist_3_joint"/>
  </actuator>

  <keyframe>
    <key name="home" qpos="-1.5708 -1.5708 1.5708 -1.5708 -1.5708 0" ctrl="-1.5708 -1.5708 1.5708 -1.5708 -1.5708 0"/>
    <!-- <key name="Initial_pos" qpos="0.0 -1.1 1.8 0.0 3.14 0.0" ctrl="0.0 0.0 0.0 0.0 0.0 0.0"/> -->
    <!-- <key name="Init_pos" qpos="0.01 -0.88 1.73 -0.570 3.14 0" qvel="0 -0.69 1.35 -0.570 3.14 0"/> -->
    <key name="Init_pos" qpos="0.01 -0.88 1.73 -0.570 3.14 0" qvel="0 -0.69 1.35 -0.570 3.14 0"/>
    <!-- <key name="middle_point_1" qpos="-0.08 -1.07 1.83 -1.19 3.14 0" qvel="0 -0.69 1.35 -0.570 3.14 0"/> -->
    <key name="middle_point_1" qpos="-0.03 -0.942 1.7 -0.570 3.14 0" qvel="0 -0.69 1.35 -0.570 3.14 0"/>
    <key name="middle_point_2" qpos="-0.15 -1.13 1.83 -1.19 3.14 0" qvel="0 -0.69 1.35 -0.570 3.14 0"/>
    <key name="middle_point_3" qpos="-0.27 -1.19 1.79 -1.19 3.14 0" qvel="0 -0.69 1.35 -0.570 3.14 0"/>
    <key name="middle_point_4" qpos="-0.39 -1.22 1.73 -1.19 3.14 0" qvel="0 -0.69 1.35 -0.570 3.14 0"/>
    <key name="middle_point_5" qpos="-0.51 -1.26 1.6 -1.19 3.14 0" qvel="0 -0.69 1.35 -0.570 3.14 0"/>
    <key name="middle_point_6" qpos="-0.63 -1.19 1.45 -1.19 3.14 0" qvel="0 -0.69 1.35 -0.570 3.14 0"/>
    <key name="middle_point_7" qpos="-0.73 -1.01 1.31 -1.19 3.14 0" qvel="0 -0.69 1.35 -0.570 3.14 0"/>
    <key name="middle_point_8" qpos="-0.82 -0.817 1.16 -1.19 3.14 0" qvel="0 -0.69 1.35 -0.570 3.14 0"/>
    <key name="goal_point" qpos="-0.86 -0.628 0.848 -0.628 3.14 0" qvel="0 -0.69 1.35 -0.570 3.14 0"/>
  </keyframe>
</mujoco>
